Yes, it is necessary for classes that represent exceptions to be derived from the base class Exception. This allows for better organization and handling of different types of exceptions.

Nested exception handling in Python allows you to handle exceptions within other exception handlers. When an exception occurs within a try block, Python checks if there is an appropriate except block to handle it. If there is no matching except block, the exception is propagated to the outer try block (if any). This process continues until an appropriate except block is found or until the exception reaches the top-level of the program.

Here's an example to illustrate nested exception handling:

```python
try:
    try:
        # Some code that may raise an exception
        result = 10 / 0
    except ZeroDivisionError:
        print("Caught ZeroDivisionError inside inner try block")
        # Raising another exception
        raise ValueError("Something went wrong")
except ValueError as e:
    print("Caught ValueError inside outer try block:", str(e))
```

In this example, we have an inner try block that attempts to divide 10 by 0, which raises a ZeroDivisionError. We catch this exception inside the inner try block and print a message. Then, we raise a ValueError inside the inner try block. This exception propagates to the outer try block, where we catch it and print another message.

Nested exception handling can be useful when you want to handle specific exceptions at different levels of your code or when you need to perform different actions based on the type of exception that occurred.

I hope this helps! Let me know if you have any further questions.The `finally` block in Python exception handling is used to define a set of statements that will be executed regardless of whether an exception occurs or not. It provides a way to clean up resources, release locks, or perform any necessary actions that should always be executed, regardless of whether an exception is raised or not.

Here's an example to illustrate the use of a `finally` block:

```python
try:
    # Some code that may raise an exception
    file = open("example.txt", "r")
    # Perform some operations on the file
except FileNotFoundError:
    print("File not found!")
finally:
    # This block will always be executed
    if file:
        file.close()
    print("Finally block executed")
```

In this example, we try to open a file called "example.txt" for reading. If the file is not found, a `FileNotFoundError` is raised, and the corresponding except block is executed. However, regardless of whether an exception occurs or not, the finally block is always executed. In this case, we close the file if it was successfully opened and print a message to indicate that the finally block has been executed.

The `finally` block is useful when you want to ensure that certain cleanup or finalization tasks are performed, such as closing files, releasing resources, or restoring the program to a known state, regardless of whether an exception occurred or not.

I hope this clarifies the use of the `finally` block in exception handling. Let me know if you have any further questions!. Here's a Python program that receives 10 integers, stores them and their cubes in a dictionary, and raises custom exceptions if the numbers entered are too small or too big:

```python
class NumberTooSmall(Exception):
    pass

class NumberTooBig(Exception):
    pass

def store_numbers():
    numbers_dict = {}
    for _ in range(10):
        try:
            num = int(input("Enter an integer: "))
            if num < 3:
                raise NumberTooSmall
            if num > 30:
                raise NumberTooBig
            numbers_dict[num] = num ** 3
        except NumberTooSmall:
            print("Number is too small. Please enter a number greater than or equal to 3.")
        except NumberTooBig:
            print("Number is too big. Please enter a number less than or equal to 30.")
        except ValueError:
            print("Invalid input. Please enter an integer.")
    print("Dictionary contents:")
    for num, cube in numbers_dict.items():
        print(f"{num}: {cube}")

store_numbers()
```

In this program, we define two custom exception classes, `NumberTooSmall` and `NumberTooBig`. We then use a `try-except` block to handle any exceptions that may occur when receiving input from the user. If the number entered is less than 3, we raise the `NumberTooSmall` exception, and if the number entered is more than 30, we raise the `NumberTooBig` exception. The numbers and their cubes are stored in a dictionary, and at the end, we print the contents of the dictionary.

Please let me know if you need any further assistance!
